{
 "cells": [
  {
   "cell_type": "code",
   "execution_count": 2,
   "metadata": {},
   "outputs": [],
   "source": [
    "from sklearn.model_selection import train_test_split\n",
    "from sklearn.preprocessing import LabelEncoder\n",
    "from keras.models import Sequential\n",
    "from keras.layers import LSTM, Dense, Bidirectional, Embedding\n",
    "from keras.utils import to_categorical\n",
    "from keras.preprocessing.sequence import pad_sequences\n",
    "import numpy as np\n",
    "import pandas as pd\n",
    "\n",
    "from gensim.models import KeyedVectors\n",
    "from gensim.scripts.glove2word2vec import glove2word2vec\n",
    "\n"
   ]
  },
  {
   "cell_type": "code",
   "execution_count": 3,
   "metadata": {},
   "outputs": [
    {
     "name": "stderr",
     "output_type": "stream",
     "text": [
      "C:\\Users\\Hakan\\AppData\\Local\\Temp\\ipykernel_4580\\2826301019.py:4: DeprecationWarning: Call to deprecated `glove2word2vec` (KeyedVectors.load_word2vec_format(.., binary=False, no_header=True) loads GLoVE text vectors.).\n",
      "  glove2word2vec(glove_file, word2vec_file)\n"
     ]
    }
   ],
   "source": [
    "glove_file = 'vectors.txt'\n",
    "word2vec_file = \"word2Vec.txt\"\n",
    "\n",
    "glove2word2vec(glove_file, word2vec_file)\n",
    "glove_model = KeyedVectors.load_word2vec_format(word2vec_file, binary=False)\n",
    "df = pd.read_csv('Data.csv')\n",
    "words = df['kelime']\n",
    "X = np.array([glove_model[word] if word in glove_model else np.zeros(glove_model.vector_size) for word in words])\n",
    "y = np.array(df['köken'].tolist())"
   ]
  },
  {
   "cell_type": "code",
   "execution_count": 4,
   "metadata": {},
   "outputs": [],
   "source": [
    "label_encoder = LabelEncoder()\n",
    "\n",
    "\n",
    "y_encoded = label_encoder.fit_transform(y)\n",
    "\n",
    "\n",
    "X_train, X_test, y_train_encoded, y_test_encoded = train_test_split(X, y_encoded, test_size=0.2, random_state=42)\n",
    "\n",
    "y_train_categorical = to_categorical(y_train_encoded)\n",
    "y_test_categorical = to_categorical(y_test_encoded)\n",
    "\n",
    "\n",
    "max_sequence_length = X.shape[1]  # GloVe modeli kullanıldığında her kelimenin vektörü aynı boyutta olacaktır\n",
    "X_train_padded = pad_sequences(X_train, maxlen=max_sequence_length, padding='post')\n",
    "X_test_padded = pad_sequences(X_test, maxlen=max_sequence_length, padding='post')"
   ]
  },
  {
   "cell_type": "code",
   "execution_count": 5,
   "metadata": {},
   "outputs": [
    {
     "name": "stdout",
     "output_type": "stream",
     "text": [
      "Epoch 1/10\n"
     ]
    },
    {
     "ename": "InvalidArgumentError",
     "evalue": "Graph execution error:\n\nDetected at node sequential_1/embedding_1/embedding_lookup defined at (most recent call last):\n  File \"<frozen runpy>\", line 198, in _run_module_as_main\n\n  File \"<frozen runpy>\", line 88, in _run_code\n\n  File \"C:\\Users\\Hakan\\AppData\\Roaming\\Python\\Python311\\site-packages\\ipykernel_launcher.py\", line 17, in <module>\n\n  File \"C:\\Users\\Hakan\\AppData\\Roaming\\Python\\Python311\\site-packages\\traitlets\\config\\application.py\", line 1077, in launch_instance\n\n  File \"C:\\Users\\Hakan\\AppData\\Roaming\\Python\\Python311\\site-packages\\ipykernel\\kernelapp.py\", line 739, in start\n\n  File \"C:\\Users\\Hakan\\AppData\\Roaming\\Python\\Python311\\site-packages\\tornado\\platform\\asyncio.py\", line 205, in start\n\n  File \"c:\\Users\\Hakan\\AppData\\Local\\Programs\\Python\\Python311\\Lib\\asyncio\\base_events.py\", line 607, in run_forever\n\n  File \"c:\\Users\\Hakan\\AppData\\Local\\Programs\\Python\\Python311\\Lib\\asyncio\\base_events.py\", line 1922, in _run_once\n\n  File \"c:\\Users\\Hakan\\AppData\\Local\\Programs\\Python\\Python311\\Lib\\asyncio\\events.py\", line 80, in _run\n\n  File \"C:\\Users\\Hakan\\AppData\\Roaming\\Python\\Python311\\site-packages\\ipykernel\\kernelbase.py\", line 529, in dispatch_queue\n\n  File \"C:\\Users\\Hakan\\AppData\\Roaming\\Python\\Python311\\site-packages\\ipykernel\\kernelbase.py\", line 518, in process_one\n\n  File \"C:\\Users\\Hakan\\AppData\\Roaming\\Python\\Python311\\site-packages\\ipykernel\\kernelbase.py\", line 424, in dispatch_shell\n\n  File \"C:\\Users\\Hakan\\AppData\\Roaming\\Python\\Python311\\site-packages\\ipykernel\\kernelbase.py\", line 766, in execute_request\n\n  File \"C:\\Users\\Hakan\\AppData\\Roaming\\Python\\Python311\\site-packages\\ipykernel\\ipkernel.py\", line 429, in do_execute\n\n  File \"C:\\Users\\Hakan\\AppData\\Roaming\\Python\\Python311\\site-packages\\ipykernel\\zmqshell.py\", line 549, in run_cell\n\n  File \"C:\\Users\\Hakan\\AppData\\Roaming\\Python\\Python311\\site-packages\\IPython\\core\\interactiveshell.py\", line 3048, in run_cell\n\n  File \"C:\\Users\\Hakan\\AppData\\Roaming\\Python\\Python311\\site-packages\\IPython\\core\\interactiveshell.py\", line 3103, in _run_cell\n\n  File \"C:\\Users\\Hakan\\AppData\\Roaming\\Python\\Python311\\site-packages\\IPython\\core\\async_helpers.py\", line 129, in _pseudo_sync_runner\n\n  File \"C:\\Users\\Hakan\\AppData\\Roaming\\Python\\Python311\\site-packages\\IPython\\core\\interactiveshell.py\", line 3308, in run_cell_async\n\n  File \"C:\\Users\\Hakan\\AppData\\Roaming\\Python\\Python311\\site-packages\\IPython\\core\\interactiveshell.py\", line 3490, in run_ast_nodes\n\n  File \"C:\\Users\\Hakan\\AppData\\Roaming\\Python\\Python311\\site-packages\\IPython\\core\\interactiveshell.py\", line 3550, in run_code\n\n  File \"C:\\Users\\Hakan\\AppData\\Local\\Temp\\ipykernel_4580\\2164463497.py\", line 11, in <module>\n\n  File \"c:\\Users\\Hakan\\AppData\\Local\\Programs\\Python\\Python311\\Lib\\site-packages\\keras\\src\\utils\\traceback_utils.py\", line 65, in error_handler\n\n  File \"c:\\Users\\Hakan\\AppData\\Local\\Programs\\Python\\Python311\\Lib\\site-packages\\keras\\src\\engine\\training.py\", line 1807, in fit\n\n  File \"c:\\Users\\Hakan\\AppData\\Local\\Programs\\Python\\Python311\\Lib\\site-packages\\keras\\src\\engine\\training.py\", line 1401, in train_function\n\n  File \"c:\\Users\\Hakan\\AppData\\Local\\Programs\\Python\\Python311\\Lib\\site-packages\\keras\\src\\engine\\training.py\", line 1384, in step_function\n\n  File \"c:\\Users\\Hakan\\AppData\\Local\\Programs\\Python\\Python311\\Lib\\site-packages\\keras\\src\\engine\\training.py\", line 1373, in run_step\n\n  File \"c:\\Users\\Hakan\\AppData\\Local\\Programs\\Python\\Python311\\Lib\\site-packages\\keras\\src\\engine\\training.py\", line 1150, in train_step\n\n  File \"c:\\Users\\Hakan\\AppData\\Local\\Programs\\Python\\Python311\\Lib\\site-packages\\keras\\src\\utils\\traceback_utils.py\", line 65, in error_handler\n\n  File \"c:\\Users\\Hakan\\AppData\\Local\\Programs\\Python\\Python311\\Lib\\site-packages\\keras\\src\\engine\\training.py\", line 590, in __call__\n\n  File \"c:\\Users\\Hakan\\AppData\\Local\\Programs\\Python\\Python311\\Lib\\site-packages\\keras\\src\\utils\\traceback_utils.py\", line 65, in error_handler\n\n  File \"c:\\Users\\Hakan\\AppData\\Local\\Programs\\Python\\Python311\\Lib\\site-packages\\keras\\src\\engine\\base_layer.py\", line 1149, in __call__\n\n  File \"c:\\Users\\Hakan\\AppData\\Local\\Programs\\Python\\Python311\\Lib\\site-packages\\keras\\src\\utils\\traceback_utils.py\", line 96, in error_handler\n\n  File \"c:\\Users\\Hakan\\AppData\\Local\\Programs\\Python\\Python311\\Lib\\site-packages\\keras\\src\\engine\\sequential.py\", line 398, in call\n\n  File \"c:\\Users\\Hakan\\AppData\\Local\\Programs\\Python\\Python311\\Lib\\site-packages\\keras\\src\\engine\\functional.py\", line 515, in call\n\n  File \"c:\\Users\\Hakan\\AppData\\Local\\Programs\\Python\\Python311\\Lib\\site-packages\\keras\\src\\engine\\functional.py\", line 672, in _run_internal_graph\n\n  File \"c:\\Users\\Hakan\\AppData\\Local\\Programs\\Python\\Python311\\Lib\\site-packages\\keras\\src\\utils\\traceback_utils.py\", line 65, in error_handler\n\n  File \"c:\\Users\\Hakan\\AppData\\Local\\Programs\\Python\\Python311\\Lib\\site-packages\\keras\\src\\engine\\base_layer.py\", line 1149, in __call__\n\n  File \"c:\\Users\\Hakan\\AppData\\Local\\Programs\\Python\\Python311\\Lib\\site-packages\\keras\\src\\utils\\traceback_utils.py\", line 96, in error_handler\n\n  File \"c:\\Users\\Hakan\\AppData\\Local\\Programs\\Python\\Python311\\Lib\\site-packages\\keras\\src\\layers\\core\\embedding.py\", line 272, in call\n\nindices[21,270] = -1 is not in [0, 12539)\n\t [[{{node sequential_1/embedding_1/embedding_lookup}}]] [Op:__inference_train_function_11449]",
     "output_type": "error",
     "traceback": [
      "\u001b[1;31m---------------------------------------------------------------------------\u001b[0m",
      "\u001b[1;31mInvalidArgumentError\u001b[0m                      Traceback (most recent call last)",
      "Cell \u001b[1;32mIn[5], line 11\u001b[0m\n\u001b[0;32m      8\u001b[0m model_rnn\u001b[38;5;241m.\u001b[39mcompile(loss\u001b[38;5;241m=\u001b[39m\u001b[38;5;124m'\u001b[39m\u001b[38;5;124mcategorical_crossentropy\u001b[39m\u001b[38;5;124m'\u001b[39m, optimizer\u001b[38;5;241m=\u001b[39m\u001b[38;5;124m'\u001b[39m\u001b[38;5;124madam\u001b[39m\u001b[38;5;124m'\u001b[39m, metrics\u001b[38;5;241m=\u001b[39m[\u001b[38;5;124m'\u001b[39m\u001b[38;5;124maccuracy\u001b[39m\u001b[38;5;124m'\u001b[39m])\n\u001b[0;32m     10\u001b[0m \u001b[38;5;66;03m# Modeli eğitme\u001b[39;00m\n\u001b[1;32m---> 11\u001b[0m \u001b[43mmodel_rnn\u001b[49m\u001b[38;5;241;43m.\u001b[39;49m\u001b[43mfit\u001b[49m\u001b[43m(\u001b[49m\u001b[43mX_train_padded\u001b[49m\u001b[43m,\u001b[49m\u001b[43m \u001b[49m\u001b[43my_train_categorical\u001b[49m\u001b[43m,\u001b[49m\u001b[43m \u001b[49m\u001b[43mepochs\u001b[49m\u001b[38;5;241;43m=\u001b[39;49m\u001b[38;5;241;43m10\u001b[39;49m\u001b[43m,\u001b[49m\u001b[43m \u001b[49m\u001b[43mbatch_size\u001b[49m\u001b[38;5;241;43m=\u001b[39;49m\u001b[38;5;241;43m32\u001b[39;49m\u001b[43m,\u001b[49m\u001b[43m \u001b[49m\u001b[43mvalidation_split\u001b[49m\u001b[38;5;241;43m=\u001b[39;49m\u001b[38;5;241;43m0.1\u001b[39;49m\u001b[43m)\u001b[49m\n\u001b[0;32m     13\u001b[0m \u001b[38;5;66;03m# Test verisi üzerinde modeli değerlendirme\u001b[39;00m\n\u001b[0;32m     14\u001b[0m accuracy \u001b[38;5;241m=\u001b[39m model_rnn\u001b[38;5;241m.\u001b[39mevaluate(X_test_padded, y_test_categorical)[\u001b[38;5;241m1\u001b[39m]\n",
      "File \u001b[1;32mc:\\Users\\Hakan\\AppData\\Local\\Programs\\Python\\Python311\\Lib\\site-packages\\keras\\src\\utils\\traceback_utils.py:70\u001b[0m, in \u001b[0;36mfilter_traceback.<locals>.error_handler\u001b[1;34m(*args, **kwargs)\u001b[0m\n\u001b[0;32m     67\u001b[0m     filtered_tb \u001b[38;5;241m=\u001b[39m _process_traceback_frames(e\u001b[38;5;241m.\u001b[39m__traceback__)\n\u001b[0;32m     68\u001b[0m     \u001b[38;5;66;03m# To get the full stack trace, call:\u001b[39;00m\n\u001b[0;32m     69\u001b[0m     \u001b[38;5;66;03m# `tf.debugging.disable_traceback_filtering()`\u001b[39;00m\n\u001b[1;32m---> 70\u001b[0m     \u001b[38;5;28;01mraise\u001b[39;00m e\u001b[38;5;241m.\u001b[39mwith_traceback(filtered_tb) \u001b[38;5;28;01mfrom\u001b[39;00m \u001b[38;5;28;01mNone\u001b[39;00m\n\u001b[0;32m     71\u001b[0m \u001b[38;5;28;01mfinally\u001b[39;00m:\n\u001b[0;32m     72\u001b[0m     \u001b[38;5;28;01mdel\u001b[39;00m filtered_tb\n",
      "File \u001b[1;32mc:\\Users\\Hakan\\AppData\\Local\\Programs\\Python\\Python311\\Lib\\site-packages\\tensorflow\\python\\eager\\execute.py:53\u001b[0m, in \u001b[0;36mquick_execute\u001b[1;34m(op_name, num_outputs, inputs, attrs, ctx, name)\u001b[0m\n\u001b[0;32m     51\u001b[0m \u001b[38;5;28;01mtry\u001b[39;00m:\n\u001b[0;32m     52\u001b[0m   ctx\u001b[38;5;241m.\u001b[39mensure_initialized()\n\u001b[1;32m---> 53\u001b[0m   tensors \u001b[38;5;241m=\u001b[39m pywrap_tfe\u001b[38;5;241m.\u001b[39mTFE_Py_Execute(ctx\u001b[38;5;241m.\u001b[39m_handle, device_name, op_name,\n\u001b[0;32m     54\u001b[0m                                       inputs, attrs, num_outputs)\n\u001b[0;32m     55\u001b[0m \u001b[38;5;28;01mexcept\u001b[39;00m core\u001b[38;5;241m.\u001b[39m_NotOkStatusException \u001b[38;5;28;01mas\u001b[39;00m e:\n\u001b[0;32m     56\u001b[0m   \u001b[38;5;28;01mif\u001b[39;00m name \u001b[38;5;129;01mis\u001b[39;00m \u001b[38;5;129;01mnot\u001b[39;00m \u001b[38;5;28;01mNone\u001b[39;00m:\n",
      "\u001b[1;31mInvalidArgumentError\u001b[0m: Graph execution error:\n\nDetected at node sequential_1/embedding_1/embedding_lookup defined at (most recent call last):\n  File \"<frozen runpy>\", line 198, in _run_module_as_main\n\n  File \"<frozen runpy>\", line 88, in _run_code\n\n  File \"C:\\Users\\Hakan\\AppData\\Roaming\\Python\\Python311\\site-packages\\ipykernel_launcher.py\", line 17, in <module>\n\n  File \"C:\\Users\\Hakan\\AppData\\Roaming\\Python\\Python311\\site-packages\\traitlets\\config\\application.py\", line 1077, in launch_instance\n\n  File \"C:\\Users\\Hakan\\AppData\\Roaming\\Python\\Python311\\site-packages\\ipykernel\\kernelapp.py\", line 739, in start\n\n  File \"C:\\Users\\Hakan\\AppData\\Roaming\\Python\\Python311\\site-packages\\tornado\\platform\\asyncio.py\", line 205, in start\n\n  File \"c:\\Users\\Hakan\\AppData\\Local\\Programs\\Python\\Python311\\Lib\\asyncio\\base_events.py\", line 607, in run_forever\n\n  File \"c:\\Users\\Hakan\\AppData\\Local\\Programs\\Python\\Python311\\Lib\\asyncio\\base_events.py\", line 1922, in _run_once\n\n  File \"c:\\Users\\Hakan\\AppData\\Local\\Programs\\Python\\Python311\\Lib\\asyncio\\events.py\", line 80, in _run\n\n  File \"C:\\Users\\Hakan\\AppData\\Roaming\\Python\\Python311\\site-packages\\ipykernel\\kernelbase.py\", line 529, in dispatch_queue\n\n  File \"C:\\Users\\Hakan\\AppData\\Roaming\\Python\\Python311\\site-packages\\ipykernel\\kernelbase.py\", line 518, in process_one\n\n  File \"C:\\Users\\Hakan\\AppData\\Roaming\\Python\\Python311\\site-packages\\ipykernel\\kernelbase.py\", line 424, in dispatch_shell\n\n  File \"C:\\Users\\Hakan\\AppData\\Roaming\\Python\\Python311\\site-packages\\ipykernel\\kernelbase.py\", line 766, in execute_request\n\n  File \"C:\\Users\\Hakan\\AppData\\Roaming\\Python\\Python311\\site-packages\\ipykernel\\ipkernel.py\", line 429, in do_execute\n\n  File \"C:\\Users\\Hakan\\AppData\\Roaming\\Python\\Python311\\site-packages\\ipykernel\\zmqshell.py\", line 549, in run_cell\n\n  File \"C:\\Users\\Hakan\\AppData\\Roaming\\Python\\Python311\\site-packages\\IPython\\core\\interactiveshell.py\", line 3048, in run_cell\n\n  File \"C:\\Users\\Hakan\\AppData\\Roaming\\Python\\Python311\\site-packages\\IPython\\core\\interactiveshell.py\", line 3103, in _run_cell\n\n  File \"C:\\Users\\Hakan\\AppData\\Roaming\\Python\\Python311\\site-packages\\IPython\\core\\async_helpers.py\", line 129, in _pseudo_sync_runner\n\n  File \"C:\\Users\\Hakan\\AppData\\Roaming\\Python\\Python311\\site-packages\\IPython\\core\\interactiveshell.py\", line 3308, in run_cell_async\n\n  File \"C:\\Users\\Hakan\\AppData\\Roaming\\Python\\Python311\\site-packages\\IPython\\core\\interactiveshell.py\", line 3490, in run_ast_nodes\n\n  File \"C:\\Users\\Hakan\\AppData\\Roaming\\Python\\Python311\\site-packages\\IPython\\core\\interactiveshell.py\", line 3550, in run_code\n\n  File \"C:\\Users\\Hakan\\AppData\\Local\\Temp\\ipykernel_4580\\2164463497.py\", line 11, in <module>\n\n  File \"c:\\Users\\Hakan\\AppData\\Local\\Programs\\Python\\Python311\\Lib\\site-packages\\keras\\src\\utils\\traceback_utils.py\", line 65, in error_handler\n\n  File \"c:\\Users\\Hakan\\AppData\\Local\\Programs\\Python\\Python311\\Lib\\site-packages\\keras\\src\\engine\\training.py\", line 1807, in fit\n\n  File \"c:\\Users\\Hakan\\AppData\\Local\\Programs\\Python\\Python311\\Lib\\site-packages\\keras\\src\\engine\\training.py\", line 1401, in train_function\n\n  File \"c:\\Users\\Hakan\\AppData\\Local\\Programs\\Python\\Python311\\Lib\\site-packages\\keras\\src\\engine\\training.py\", line 1384, in step_function\n\n  File \"c:\\Users\\Hakan\\AppData\\Local\\Programs\\Python\\Python311\\Lib\\site-packages\\keras\\src\\engine\\training.py\", line 1373, in run_step\n\n  File \"c:\\Users\\Hakan\\AppData\\Local\\Programs\\Python\\Python311\\Lib\\site-packages\\keras\\src\\engine\\training.py\", line 1150, in train_step\n\n  File \"c:\\Users\\Hakan\\AppData\\Local\\Programs\\Python\\Python311\\Lib\\site-packages\\keras\\src\\utils\\traceback_utils.py\", line 65, in error_handler\n\n  File \"c:\\Users\\Hakan\\AppData\\Local\\Programs\\Python\\Python311\\Lib\\site-packages\\keras\\src\\engine\\training.py\", line 590, in __call__\n\n  File \"c:\\Users\\Hakan\\AppData\\Local\\Programs\\Python\\Python311\\Lib\\site-packages\\keras\\src\\utils\\traceback_utils.py\", line 65, in error_handler\n\n  File \"c:\\Users\\Hakan\\AppData\\Local\\Programs\\Python\\Python311\\Lib\\site-packages\\keras\\src\\engine\\base_layer.py\", line 1149, in __call__\n\n  File \"c:\\Users\\Hakan\\AppData\\Local\\Programs\\Python\\Python311\\Lib\\site-packages\\keras\\src\\utils\\traceback_utils.py\", line 96, in error_handler\n\n  File \"c:\\Users\\Hakan\\AppData\\Local\\Programs\\Python\\Python311\\Lib\\site-packages\\keras\\src\\engine\\sequential.py\", line 398, in call\n\n  File \"c:\\Users\\Hakan\\AppData\\Local\\Programs\\Python\\Python311\\Lib\\site-packages\\keras\\src\\engine\\functional.py\", line 515, in call\n\n  File \"c:\\Users\\Hakan\\AppData\\Local\\Programs\\Python\\Python311\\Lib\\site-packages\\keras\\src\\engine\\functional.py\", line 672, in _run_internal_graph\n\n  File \"c:\\Users\\Hakan\\AppData\\Local\\Programs\\Python\\Python311\\Lib\\site-packages\\keras\\src\\utils\\traceback_utils.py\", line 65, in error_handler\n\n  File \"c:\\Users\\Hakan\\AppData\\Local\\Programs\\Python\\Python311\\Lib\\site-packages\\keras\\src\\engine\\base_layer.py\", line 1149, in __call__\n\n  File \"c:\\Users\\Hakan\\AppData\\Local\\Programs\\Python\\Python311\\Lib\\site-packages\\keras\\src\\utils\\traceback_utils.py\", line 96, in error_handler\n\n  File \"c:\\Users\\Hakan\\AppData\\Local\\Programs\\Python\\Python311\\Lib\\site-packages\\keras\\src\\layers\\core\\embedding.py\", line 272, in call\n\nindices[21,270] = -1 is not in [0, 12539)\n\t [[{{node sequential_1/embedding_1/embedding_lookup}}]] [Op:__inference_train_function_11449]"
     ]
    }
   ],
   "source": [
    "\n",
    "model_rnn = Sequential()\n",
    "model_rnn.add(Embedding(input_dim=X.shape[0], output_dim=X.shape[1], input_length=max_sequence_length))\n",
    "model_rnn.add(Bidirectional(LSTM(100)))\n",
    "model_rnn.add(Dense(len(set(y)), activation='softmax'))\n",
    "\n",
    "\n",
    "model_rnn.compile(loss='categorical_crossentropy', optimizer='adam', metrics=['accuracy'])\n",
    "\n",
    "\n",
    "model_rnn.fit(X_train_padded, y_train_categorical, epochs=10, batch_size=32, validation_split=0.1)\n",
    "\n",
    "accuracy = model_rnn.evaluate(X_test_padded, y_test_categorical)[1]\n",
    "print(f\"Model Accuracy: {accuracy}\")"
   ]
  }
 ],
 "metadata": {
  "kernelspec": {
   "display_name": "Python 3",
   "language": "python",
   "name": "python3"
  },
  "language_info": {
   "codemirror_mode": {
    "name": "ipython",
    "version": 3
   },
   "file_extension": ".py",
   "mimetype": "text/x-python",
   "name": "python",
   "nbconvert_exporter": "python",
   "pygments_lexer": "ipython3",
   "version": "3.11.5"
  }
 },
 "nbformat": 4,
 "nbformat_minor": 2
}
